<?xml version="1.0" encoding="utf-8"?>
<!-- This URDF was automatically created by SolidWorks to URDF Exporter! Originally created by Stephen Brawner (brawner@gmail.com) 
     Commit Version: 1.6.0-1-g15f4949  Build Version: 1.6.7594.29634
     For more information, please see http://wiki.ros.org/sw_urdf_exporter -->
<robot
  name="bigmama0310">
  <link
    name="Link_0">
    <inertial>
      <origin
        xyz="-0.0036197 -0.0088605 0.029488"
        rpy="0 0 0" />
      <mass
        value="0.80666" />
      <inertia
        ixx="0.0014974"
        ixy="-1.2947E-05"
        ixz="1.4235E-05"
        iyy="0.0014446"
        iyz="-7.5473E-06"
        izz="0.0010286" />
    </inertial>
    <visual>
      <origin
        xyz="0 0 0"
        rpy="0 0 0" />
      <geometry>
        <mesh
          filename="package://bigmama0310/meshes/Link_0.STL" />
      </geometry>
      <material
        name="">
        <color
          rgba="0.79216 0.81961 0.93333 1" />
      </material>
    </visual>
    <collision>
      <origin
        xyz="0 0 0"
        rpy="0 0 0" />
      <geometry>
        <mesh
          filename="package://bigmama0310/meshes/Link_0.STL" />
      </geometry>
    </collision>
  </link>
  <link
    name="Link_1">
    <inertial>
      <origin
        xyz="-6.6613E-16 0.12 0.014813"
        rpy="0 0 0" />
      <mass
        value="0.28238" />
      <inertia
        ixx="0.0027445"
        ixy="4.8493E-20"
        ixz="4.7639E-21"
        iyy="0.00019508"
        iyz="-5.2573E-20"
        izz="0.0029159" />
    </inertial>
    <visual>
      <origin
        xyz="0 0 0"
        rpy="0 0 0" />
      <geometry>
        <mesh
          filename="package://bigmama0310/meshes/Link_1.STL" />
      </geometry>
      <material
        name="">
        <color
          rgba="0.79216 0.81961 0.93333 1" />
      </material>
    </visual>
    <collision>
      <origin
        xyz="0 0 0"
        rpy="0 0 0" />
      <geometry>
        <mesh
          filename="package://bigmama0310/meshes/Link_1.STL" />
      </geometry>
    </collision>
  </link>
  <joint
    name="Joint_1"
    type="revolute">
    <origin
      xyz="0.022 0 0.155"
      rpy="1.5708 0 1.5708" />
    <parent
      link="Link_0" />
    <child
      link="Link_1" />
    <axis
      xyz="0 0 -1" />
    <limit
      lower="-3.14"
      upper="3.14"
      effort="100"
      velocity="0.25" />
  </joint>
  <link
    name="Link_2">
    <inertial>
      <origin
        xyz="1.1102E-16 0.098184 -0.051898"
        rpy="0 0 0" />
      <mass
        value="0.34516" />
      <inertia
        ixx="0.0036332"
        ixy="3.4187E-18"
        ixz="-4.4355E-19"
        iyy="0.00034405"
        iyz="0.00024115"
        izz="0.0037914" />
    </inertial>
    <visual>
      <origin
        xyz="0 0 0"
        rpy="0 0 0" />
      <geometry>
        <mesh
          filename="package://bigmama0310/meshes/Link_2.STL" />
      </geometry>
      <material
        name="">
        <color
          rgba="0.79216 0.81961 0.93333 1" />
      </material>
    </visual>
    <collision>
      <origin
        xyz="0 0 0"
        rpy="0 0 0" />
      <geometry>
        <mesh
          filename="package://bigmama0310/meshes/Link_2.STL" />
      </geometry>
    </collision>
  </link>
  <joint
    name="Joint_2"
    type="revolute">
    <origin
      xyz="0 0.24 0"
      rpy="0 0 0" />
    <parent
      link="Link_1" />
    <child
      link="Link_2" />
    <axis
      xyz="0 0 -1" />
    <limit
      lower="-3.14"
      upper="3.14"
      effort="100"
      velocity="0.25" />
  </joint>
  <link
    name="Link_3">
    <inertial>
      <origin
        xyz="0.018256 0.077688 0.029219"
        rpy="0 0 0" />
      <mass
        value="0.40524" />
      <inertia
        ixx="0.0010067"
        ixy="-1.0212E-05"
        ixz="-1.2958E-05"
        iyy="0.00027741"
        iyz="1.4235E-05"
        izz="0.0011025" />
    </inertial>
    <visual>
      <origin
        xyz="0 0 0"
        rpy="0 0 0" />
      <geometry>
        <mesh
          filename="package://bigmama0310/meshes/Link_3.STL" />
      </geometry>
      <material
        name="">
        <color
          rgba="0.79216 0.81961 0.93333 1" />
      </material>
    </visual>
    <collision>
      <origin
        xyz="0 0 0"
        rpy="0 0 0" />
      <geometry>
        <mesh
          filename="package://bigmama0310/meshes/Link_3.STL" />
      </geometry>
    </collision>
  </link>
  <joint
    name="Joint_3"
    type="revolute">
    <origin
      xyz="0 0.24 -0.0442"
      rpy="0 0 0" />
    <parent
      link="Link_2" />
    <child
      link="Link_3" />
    <axis
      xyz="0 0 1" />
    <limit
      lower="-3.14"
      upper="3.14"
      effort="100"
      velocity="0.25" />
  </joint>
  <link
    name="Link_4">
    <inertial>
      <origin
        xyz="-0.0019821 -5.3163E-05 -0.0061503"
        rpy="0 0 0" />
      <mass
        value="0.11687" />
      <inertia
        ixx="0.00032202"
        ixy="1.2427E-08"
        ixz="-2.8556E-06"
        iyy="0.00028102"
        iyz="7.1483E-09"
        izz="0.00059866" />
    </inertial>
    <visual>
      <origin
        xyz="0 0 0"
        rpy="0 0 0" />
      <geometry>
        <mesh
          filename="package://bigmama0310/meshes/Link_4.STL" />
      </geometry>
      <material
        name="">
        <color
          rgba="0.79216 0.81961 0.93333 1" />
      </material>
    </visual>
    <collision>
      <origin
        xyz="0 0 0"
        rpy="0 0 0" />
      <geometry>
        <mesh
          filename="package://bigmama0310/meshes/Link_4.STL" />
      </geometry>
    </collision>
  </link>
  <joint
    name="Joint_4"
    type="revolute">
    <origin
      xyz="0 0.145 0.022"
      rpy="1.5708 0 0" />
    <parent
      link="Link_3" />
    <child
      link="Link_4" />
    <axis
      xyz="0 0 -1" />
    <limit
      lower="0"
      upper="0.0001"
      effort="50"
      velocity="0.0001" />
    <dynamics
      damping="10"
      friction="10" />
  </joint>
  <link
    name="Link_forwardsucker">
    <inertial>
      <origin
        xyz="0.00019923 2.8479E-08 -0.00091557"
        rpy="0 0 0" />
      <mass
        value="0.094825" />
      <inertia
        ixx="3.8502E-05"
        ixy="2.9201E-10"
        ixz="-2.0628E-07"
        iyy="3.7774E-05"
        iyz="1.0266E-11"
        izz="5.0867E-05" />
    </inertial>
    <visual>
      <origin
        xyz="0 0 0"
        rpy="0 0 0" />
      <geometry>
        <mesh
          filename="package://bigmama0310/meshes/Link_forwardsucker.STL" />
      </geometry>
      <material
        name="">
        <color
          rgba="0.79216 0.81961 0.93333 1" />
      </material>
    </visual>
    <collision>
      <origin
        xyz="0 0 0"
        rpy="0 0 0" />
      <geometry>
        <mesh
          filename="package://bigmama0310/meshes/Link_forwardsucker.STL" />
      </geometry>
    </collision>
  </link>
  <joint
    name="Joint_forwardsucker"
    type="revolute">
    <origin
      xyz="0.1 0 -0.035"
      rpy="0 0 0" />
    <parent
      link="Link_4" />
    <child
      link="Link_forwardsucker" />
    <axis
      xyz="0 0 -1" />
    <limit
      lower="0"
      upper="0.0001"
      effort="50"
      velocity="0.0001" />
    <dynamics
      damping="10"
      friction="10" />
  </joint>
  <link
    name="Link_innersucker">
    <inertial>
      <origin
        xyz="-0.00019923 -3.1852E-08 -0.00091557"
        rpy="0 0 0" />
      <mass
        value="0.094825" />
      <inertia
        ixx="3.8502E-05"
        ixy="2.7231E-10"
        ixz="2.0628E-07"
        iyy="3.7774E-05"
        iyz="-1.9159E-11"
        izz="5.0867E-05" />
    </inertial>
    <visual>
      <origin
        xyz="0 0 0"
        rpy="0 0 0" />
      <geometry>
        <mesh
          filename="package://bigmama0310/meshes/Link_innersucker.STL" />
      </geometry>
      <material
        name="">
        <color
          rgba="0.79216 0.81961 0.93333 1" />
      </material>
    </visual>
    <collision>
      <origin
        xyz="0 0 0"
        rpy="0 0 0" />
      <geometry>
        <mesh
          filename="package://bigmama0310/meshes/Link_innersucker.STL" />
      </geometry>
    </collision>
  </link>
  <joint
    name="Joint_innersucker"
    type="revolute">
    <origin
      xyz="-0.05 -0.084379 -0.038337"
      rpy="0.078319 0 0" />
    <parent
      link="Link_4" />
    <child
      link="Link_innersucker" />
    <axis
      xyz="0 0 -1" />
    <limit
      lower="0"
      upper="0.0001"
      effort="50"
      velocity="0.0001" />
    <dynamics
      damping="10"
      friction="10" />
  </joint>
  <link
    name="Link_extersucker">
    <inertial>
      <origin
        xyz="-0.00019923 -2.3068E-08 -0.00091557"
        rpy="0 0 0" />
      <mass
        value="0.094825" />
      <inertia
        ixx="3.8502E-05"
        ixy="2.7492E-10"
        ixz="2.0628E-07"
        iyy="3.7774E-05"
        iyz="-5.9501E-12"
        izz="5.0867E-05" />
    </inertial>
    <visual>
      <origin
        xyz="0 0 0"
        rpy="0 0 0" />
      <geometry>
        <mesh
          filename="package://bigmama0310/meshes/Link_extersucker.STL" />
      </geometry>
      <material
        name="">
        <color
          rgba="0.79216 0.81961 0.93333 1" />
      </material>
    </visual>
    <collision>
      <origin
        xyz="0 0 0"
        rpy="0 0 0" />
      <geometry>
        <mesh
          filename="package://bigmama0310/meshes/Link_extersucker.STL" />
      </geometry>
    </collision>
  </link>
  <joint
    name="Joint_extersucker"
    type="revolute">
    <origin
      xyz="-0.05 0.084379 -0.038337"
      rpy="-0.078319 0 0" />
    <parent
      link="Link_4" />
    <child
      link="Link_extersucker" />
    <axis
      xyz="0 0 -1" />
    <limit
      lower="0"
      upper="0.0001"
      effort="50"
      velocity="0.0001" />
    <dynamics
      damping="10"
      friction="10" />
  </joint>
</robot>