<?xml version="1.0" encoding="utf-8"?>
<!-- This URDF was automatically created by SolidWorks to URDF Exporter! Originally created by Stephen Brawner (brawner@gmail.com) 
     Commit Version: 1.6.0-1-g15f4949  Build Version: 1.6.7594.29634
     For more information, please see http://wiki.ros.org/sw_urdf_exporter -->
<robot
  name="biped_wj1109">
  <link
    name="base_link">
    <inertial>
      <origin
        xyz="-0.00010023 -0.025972 0.049495"
        rpy="0 0 0" />
      <mass
        value="1.2781" />
      <inertia
        ixx="0.0021243"
        ixy="4.4949E-08"
        ixz="2.4819E-07"
        iyy="0.0018554"
        iyz="0.00018522"
        izz="0.0031699" />
    </inertial>
    <visual>
      <origin
        xyz="0 0 0"
        rpy="0 0 0" />
      <geometry>
        <mesh
          filename="package://biped_wj1109/meshes/base_link.STL" />
      </geometry>
      <material
        name="">
        <color
          rgba="0.75294 0.75294 0.75294 1" />
      </material>
    </visual>
    <collision>
      <origin
        xyz="0 0 0"
        rpy="0 0 0" />
      <geometry>
        <mesh
          filename="package://biped_wj1109/meshes/base_link.STL" />
      </geometry>
    </collision>
  </link>
  <link
    name="A_Link">
    <inertial>
      <origin
        xyz="-0.010548 4.7142E-07 0.15036"
        rpy="0 0 0" />
      <mass
        value="1.0737" />
      <inertia
        ixx="0.010166"
        ixy="-6.3111E-08"
        ixz="0.0012596"
        iyy="0.0097797"
        iyz="-3.9503E-09"
        izz="0.0020744" />
    </inertial>
    <visual>
      <origin
        xyz="0 0 0"
        rpy="0 0 0" />
      <geometry>
        <mesh
          filename="package://biped_wj1109/meshes/A_Link.STL" />
      </geometry>
      <material
        name="">
        <color
          rgba="0.79216 0.81961 0.93333 1" />
      </material>
    </visual>
    <collision>
      <origin
        xyz="0 0 0"
        rpy="0 0 0" />
      <geometry>
        <mesh
          filename="package://biped_wj1109/meshes/A_Link.STL" />
      </geometry>
    </collision>
  </link>
  <joint
    name="A"
    type="revolute">
    <origin
      xyz="0 0 0.075"
      rpy="0 0 0" />
    <parent
      link="base_link" />
    <child
      link="A_Link" />
    <axis
      xyz="0 0 1" />
    <limit
      lower="-3.14"
      upper="3.14"
      effort="500"
      velocity="1" />
  </joint>
  <link
    name="B_Link">
    <inertial>
      <origin
        xyz="3.8351E-06 -0.18523 0.010297"
        rpy="0 0 0" />
      <mass
        value="1.407" />
      <inertia
        ixx="0.025564"
        ixy="3.7004E-08"
        ixz="-9.8684E-10"
        iyy="0.002185"
        iyz="-0.0022725"
        izz="0.026056" />
    </inertial>
    <visual>
      <origin
        xyz="0 0 0"
        rpy="0 0 0" />
      <geometry>
        <mesh
          filename="package://biped_wj1109/meshes/B_Link.STL" />
      </geometry>
      <material
        name="">
        <color
          rgba="0.79216 0.81961 0.93333 1" />
      </material>
    </visual>
    <collision>
      <origin
        xyz="0 0 0"
        rpy="0 0 0" />
      <geometry>
        <mesh
          filename="package://biped_wj1109/meshes/B_Link.STL" />
      </geometry>
    </collision>
  </link>
  <joint
    name="B"
    type="revolute">
    <origin
      xyz="-0.068 0 0.25"
      rpy="-1.5708 0 1.5708" />
    <parent
      link="A_Link" />
    <child
      link="B_Link" />
    <axis
      xyz="0 0 -1" />
    <limit
      lower="-2.35"
      upper="2.35"
      effort="500"
      velocity="1" />
  </joint>
  <link
    name="C_Link">
    <inertial>
      <origin
        xyz="3.1223E-06 -0.132 -0.087027"
        rpy="0 0 0" />
      <mass
        value="1.4354" />
      <inertia
        ixx="0.02651"
        ixy="-1.2337E-07"
        ixz="-4.0239E-08"
        iyy="0.0026727"
        iyz="-0.0028223"
        izz="0.026658" />
    </inertial>
    <visual>
      <origin
        xyz="0 0 0"
        rpy="0 0 0" />
      <geometry>
        <mesh
          filename="package://biped_wj1109/meshes/C_Link.STL" />
      </geometry>
      <material
        name="">
        <color
          rgba="0.79216 0.81961 0.93333 1" />
      </material>
    </visual>
    <collision>
      <origin
        xyz="0 0 0"
        rpy="0 0 0" />
      <geometry>
        <mesh
          filename="package://biped_wj1109/meshes/C_Link.STL" />
      </geometry>
    </collision>
  </link>
  <joint
    name="C"
    type="revolute">
    <origin
      xyz="0 -0.32 -0.056"
      rpy="0 0 0" />
    <parent
      link="B_Link" />
    <child
      link="C_Link" />
    <axis
      xyz="0 0 1" />
    <limit
      lower="-2.35"
      upper="2.35"
      effort="500"
      velocity="1" />
  </joint>
  <link
    name="D_Link">
    <inertial>
      <origin
        xyz="4.7142E-07 -0.099642 0.057452"
        rpy="0 0 0" />
      <mass
        value="1.0737" />
      <inertia
        ixx="0.0097797"
        ixy="-3.9503E-09"
        ixz="-6.3111E-08"
        iyy="0.0020744"
        iyz="0.0012596"
        izz="0.010166" />
    </inertial>
    <visual>
      <origin
        xyz="0 0 0"
        rpy="0 0 0" />
      <geometry>
        <mesh
          filename="package://biped_wj1109/meshes/D_Link.STL" />
      </geometry>
      <material
        name="">
        <color
          rgba="0.79216 0.81961 0.93333 1" />
      </material>
    </visual>
    <collision>
      <origin
        xyz="0 0 0"
        rpy="0 0 0" />
      <geometry>
        <mesh
          filename="package://biped_wj1109/meshes/D_Link.STL" />
      </geometry>
    </collision>
  </link>
  <joint
    name="D"
    type="revolute">
    <origin
      xyz="0 -0.32 -0.08"
      rpy="0 0 0" />
    <parent
      link="C_Link" />
    <child
      link="D_Link" />
    <axis
      xyz="0 0 1" />
    <limit
      lower="-2.35"
      upper="2.35"
      effort="500"
      velocity="1" />
  </joint>
  <link
    name="E_Link">
    <inertial>
      <origin
        xyz="1.9372E-05 -0.025979 -0.049495"
        rpy="0 0 0" />
      <mass
        value="1.2781" />
      <inertia
        ixx="0.0021241"
        ixy="6.5701E-07"
        ixz="-3.0095E-08"
        iyy="0.0018555"
        iyz="-0.00018525"
        izz="0.0031699" />
    </inertial>
    <visual>
      <origin
        xyz="0 0 0"
        rpy="0 0 0" />
      <geometry>
        <mesh
          filename="package://biped_wj1109/meshes/E_Link.STL" />
      </geometry>
      <material
        name="">
        <color
          rgba="0.75294 0.75294 0.75294 1" />
      </material>
    </visual>
    <collision>
      <origin
        xyz="0 0 0"
        rpy="0 0 0" />
      <geometry>
        <mesh
          filename="package://biped_wj1109/meshes/E_Link.STL" />
      </geometry>
    </collision>
  </link>
  <joint
    name="E"
    type="revolute">
    <origin
      xyz="0 -0.325 0.068"
      rpy="1.5708 1.5708 0" />
    <parent
      link="D_Link" />
    <child
      link="E_Link" />
    <axis
      xyz="0 0 -1" />
    <limit
      lower="-3.14"
      upper="3.14"
      effort="500"
      velocity="1" />
  </joint>
</robot>