<?xml version="1.0" encoding="utf-8"?>
<!-- This URDF was automatically created by SolidWorks to URDF Exporter! Originally created by Stephen Brawner (brawner@gmail.com) 
     Commit Version: 1.6.0-1-g15f4949  Build Version: 1.6.7594.29634
     For more information, please see http://wiki.ros.org/sw_urdf_exporter -->
<robot
  name="bigmama9">
  <link name="dummy"> 
  </link>  
  <link
    name="Link_0">
    <inertial>
      <origin
        xyz="0.00037477 0.0023479 0.025602"
        rpy="0 0 0" />
      <mass
        value="0.66851" />
      <inertia
        ixx="0.0013719"
        ixy="-1.2212E-08"
        ixz="2.6548E-06"
        iyy="0.0014206"
        iyz="-2.2282E-05"
        izz="0.00098721" />
    </inertial>
    <visual>
      <origin
        xyz="0 0 0"
        rpy="0 0 0" />
      <geometry>
        <mesh
          filename="package://bigmama9/meshes/Link_0.STL" />
      </geometry>
      <material
        name="">
        <color
          rgba="0.79216 0.81961 0.93333 1" />
      </material>
    </visual>
    <collision>
      <origin
        xyz="0 0 0"
        rpy="0 0 0" />
      <geometry>
        <mesh
          filename="package://bigmama9/meshes/Link_0.STL" />
      </geometry>
    </collision>
  </link>
  <joint name="dummy_joint" type="fixed">
     <parent link="dummy"/>
     <child link="Link_0"/>
  </joint>
  <link
    name="Link_1">
    <inertial>
      <origin
        xyz="0.12 -5.0182E-14 0.015"
        rpy="0 0 0" />
      <mass
        value="0.2828" />
      <inertia
        ixx="0.0001953"
        ixy="-1.3373E-20"
        ixz="1.9025E-17"
        iyy="0.0027507"
        iyz="1.3416E-21"
        izz="0.0029223" />
    </inertial>
    <visual>
      <origin
        xyz="0 0 0"
        rpy="0 0 0" />
      <geometry>
        <mesh
          filename="package://bigmama9/meshes/Link_1.STL" />
      </geometry>
      <material
        name="">
        <color
          rgba="0.79216 0.81961 0.93333 1" />
      </material>
    </visual>
    <collision>
      <origin
        xyz="0 0 0"
        rpy="0 0 0" />
      <geometry>
        <mesh
          filename="package://bigmama9/meshes/Link_1.STL" />
      </geometry>
    </collision>
  </link>
  <joint
    name="Joint_1"
    type="revolute">
    <origin
      xyz="0 -0.022 0.155"
      rpy="1.5708 -1.5708 0" />
    <parent
      link="Link_0" />
    <child
      link="Link_1" />
    <axis
      xyz="0 0 -1" />
    <limit
      lower="-3.14"
      upper="3.14"
      effort="100"
      velocity="0.1" />
  </joint>
  <link
    name="Link_2">
    <inertial>
      <origin
        xyz="0.097793 7.2164E-15 -0.051815"
        rpy="0 0 0" />
      <mass
        value="0.34706" />
      <inertia
        ixx="0.00034654"
        ixy="-3.148E-18"
        ixz="0.00024386"
        iyy="0.003656"
        iyz="3.5619E-19"
        izz="0.0038143" />
    </inertial>
    <visual>
      <origin
        xyz="0 0 0"
        rpy="0 0 0" />
      <geometry>
        <mesh
          filename="package://bigmama9/meshes/Link_2.STL" />
      </geometry>
      <material
        name="">
        <color
          rgba="0.79216 0.81961 0.93333 1" />
      </material>
    </visual>
    <collision>
      <origin
        xyz="0 0 0"
        rpy="0 0 0" />
      <geometry>
        <mesh
          filename="package://bigmama9/meshes/Link_2.STL" />
      </geometry>
    </collision>
  </link>
  <joint
    name="Joint_2"
    type="revolute">
    <origin
      xyz="0.24 0 0"
      rpy="0 0 0" />
    <parent
      link="Link_1" />
    <child
      link="Link_2" />
    <axis
      xyz="0 0 -1" />
    <limit
      lower="-3.14"
      upper="3.14"
      effort="100"
      velocity="0.1" />
  </joint>
  <link
    name="Link_3">
    <inertial>
      <origin
        xyz="0.1294 0.00037477 0.024348"
        rpy="0 0 0" />
      <mass
        value="0.66851" />
      <inertia
        ixx="0.00098721"
        ixy="-2.6548E-06"
        ixz="2.2282E-05"
        iyy="0.0013719"
        iyz="-1.2403E-08"
        izz="0.0014206" />
    </inertial>
    <visual>
      <origin
        xyz="0 0 0"
        rpy="0 0 0" />
      <geometry>
        <mesh
          filename="package://bigmama9/meshes/Link_3.STL" />
      </geometry>
      <material
        name="">
        <color
          rgba="0.79216 0.81961 0.93333 1" />
      </material>
    </visual>
    <collision>
      <origin
        xyz="0 0 0"
        rpy="0 0 0" />
      <geometry>
        <mesh
          filename="package://bigmama9/meshes/Link_3.STL" />
      </geometry>
    </collision>
  </link>
  <joint
    name="Joint_3"
    type="revolute">
    <origin
      xyz="0.24 0 -0.044"
      rpy="0 0 0" />
    <parent
      link="Link_2" />
    <child
      link="Link_3" />
    <axis
      xyz="0 0 1" />
    <limit
      lower="-3.14"
      upper="3.14"
      effort="100"
      velocity="0.1" />
  </joint>
</robot>
